PS D:\ttemp1\python23\fastapi-postgresql-crud> cd app
PS D:\ttemp1\python23\fastapi-postgresql-crud\app> uvicorn main:app --reload
INFO:     Will watch for changes in these directories: ['D:\\ttemp1\\python23\\fastapi-postgresql-crud\\app']
INFO:     Uvicorn running on http://127.0.0.1:8000 (Press CTRL+C to quit)
INFO:     Started reloader process [6132] using WatchFiles
C:\python\lib\site-packages\pydantic\_internal\_config.py:261: UserWarning: Valid config keys have changed in V2:
* 'orm_mode' has been renamed to 'from_attributes'
  warnings.warn(message, UserWarning)
Process SpawnProcess-1:
Traceback (most recent call last):
  File "C:\python\lib\multiprocessing\process.py", line 314, in _bootstrap
    self.run()
  File "C:\python\lib\multiprocessing\process.py", line 108, in run
    self._target(*self._args, **self._kwargs)
  File "C:\python\lib\site-packages\uvicorn\_subprocess.py", line 76, in subprocess_started
    target(sockets=sockets)
  File "C:\python\lib\site-packages\uvicorn\server.py", line 61, in run
    return asyncio.run(self.serve(sockets=sockets))
  File "C:\python\lib\asyncio\runners.py", line 44, in run
    return loop.run_until_complete(main)
  File "C:\python\lib\asyncio\base_events.py", line 646, in run_until_complete
    return future.result()
  File "C:\python\lib\site-packages\uvicorn\server.py", line 68, in serve
    config.load()
  File "C:\python\lib\site-packages\uvicorn\config.py", line 467, in load
    self.loaded_app = import_from_string(self.app)
  File "C:\python\lib\site-packages\uvicorn\importer.py", line 21, in import_from_string
    module = importlib.import_module(module_str)
  File "C:\python\lib\importlib\__init__.py", line 126, in import_module
    return _bootstrap._gcd_import(name[level:], package, level)
  File "<frozen importlib._bootstrap>", line 1050, in _gcd_import
  File "<frozen importlib._bootstrap>", line 1027, in _find_and_load
  File "<frozen importlib._bootstrap>", line 1006, in _find_and_load_unlocked
  File "<frozen importlib._bootstrap>", line 688, in _load_unlocked
  File "<frozen importlib._bootstrap_external>", line 883, in exec_module
  File "<frozen importlib._bootstrap>", line 241, in _call_with_frames_removed
  File "D:\ttemp1\python23\fastapi-postgresql-crud\app\main.py", line 3, in <module>
    from routes import router
  File "D:\ttemp1\python23\fastapi-postgresql-crud\app\routes.py", line 5, in <module>
    from schemas import BookSchema, Request, Response, RequestBook
  File "D:\ttemp1\python23\fastapi-postgresql-crud\app\schemas.py", line 32, in <module>
    class Request(GenericModel_1,
  File "C:\python\lib\site-packages\pydantic\_internal\_model_construction.py", line 153, in __new__
    raise TypeError(error_message)
TypeError: All parameters must be present on typing.Generic; you should inherit from typing.Generic[~BoundT, ~T]
WARNING:  WatchFiles detected changes in 'schemas.py'. Reloading...
C:\python\lib\site-packages\pydantic\_internal\_config.py:261: UserWarning: Valid config keys have changed in V2:
* 'orm_mode' has been renamed to 'from_attributes'
  warnings.warn(message, UserWarning)
Process SpawnProcess-2:
Traceback (most recent call last):
  File "C:\python\lib\multiprocessing\process.py", line 314, in _bootstrap
    self.run()
  File "C:\python\lib\multiprocessing\process.py", line 108, in run
    self._target(*self._args, **self._kwargs)
  File "C:\python\lib\site-packages\uvicorn\_subprocess.py", line 76, in subprocess_started
    target(sockets=sockets)
  File "C:\python\lib\site-packages\uvicorn\server.py", line 61, in run
    return asyncio.run(self.serve(sockets=sockets))
  File "C:\python\lib\asyncio\runners.py", line 44, in run
    return loop.run_until_complete(main)
  File "C:\python\lib\asyncio\base_events.py", line 646, in run_until_complete
    return future.result()
  File "C:\python\lib\site-packages\uvicorn\server.py", line 68, in serve
    config.load()
  File "C:\python\lib\site-packages\uvicorn\config.py", line 467, in load
    self.loaded_app = import_from_string(self.app)
  File "C:\python\lib\site-packages\uvicorn\importer.py", line 21, in import_from_string
    module = importlib.import_module(module_str)
  File "C:\python\lib\importlib\__init__.py", line 126, in import_module
    return _bootstrap._gcd_import(name[level:], package, level)
  File "<frozen importlib._bootstrap>", line 1050, in _gcd_import
  File "<frozen importlib._bootstrap>", line 1027, in _find_and_load
  File "<frozen importlib._bootstrap>", line 1006, in _find_and_load_unlocked
  File "<frozen importlib._bootstrap>", line 688, in _load_unlocked
  File "<frozen importlib._bootstrap_external>", line 883, in exec_module
  File "<frozen importlib._bootstrap>", line 241, in _call_with_frames_removed
  File "D:\ttemp1\python23\fastapi-postgresql-crud\app\main.py", line 3, in <module>
    from routes import router
  File "D:\ttemp1\python23\fastapi-postgresql-crud\app\routes.py", line 5, in <module>
    from schemas import BookSchema, Request, Response, RequestBook
  File "D:\ttemp1\python23\fastapi-postgresql-crud\app\schemas.py", line 41, in <module>
    class Response(GenericModel_1,
  File "C:\python\lib\site-packages\pydantic\_internal\_model_construction.py", line 153, in __new__
    raise TypeError(error_message)
TypeError: All parameters must be present on typing.Generic; you should inherit from typing.Generic[~BoundT, ~T]
WARNING:  WatchFiles detected changes in 'schemas.py'. Reloading...
C:\python\lib\site-packages\pydantic\_internal\_config.py:261: UserWarning: Valid config keys have changed in V2:
* 'orm_mode' has been renamed to 'from_attributes'
  warnings.warn(message, UserWarning)
Process SpawnProcess-3:
Traceback (most recent call last):
  File "C:\python\lib\site-packages\sqlalchemy\engine\base.py", line 145, in __init__
    self._dbapi_connection = engine.raw_connection()
  File "C:\python\lib\site-packages\sqlalchemy\engine\base.py", line 3288, in raw_connection
    return self.pool.connect()
  File "C:\python\lib\site-packages\sqlalchemy\pool\base.py", line 452, in connect
    return _ConnectionFairy._checkout(self)
  File "C:\python\lib\site-packages\sqlalchemy\pool\base.py", line 1267, in _checkout
    fairy = _ConnectionRecord.checkout(pool)
  File "C:\python\lib\site-packages\sqlalchemy\pool\base.py", line 716, in checkout
    rec = pool._do_get()
  File "C:\python\lib\site-packages\sqlalchemy\pool\impl.py", line 169, in _do_get
    with util.safe_reraise():
  File "C:\python\lib\site-packages\sqlalchemy\util\langhelpers.py", line 147, in __exit__
    raise exc_value.with_traceback(exc_tb)
  File "C:\python\lib\site-packages\sqlalchemy\pool\impl.py", line 167, in _do_get
    return self._create_connection()
  File "C:\python\lib\site-packages\sqlalchemy\pool\base.py", line 393, in _create_connection
    return _ConnectionRecord(self)
  File "C:\python\lib\site-packages\sqlalchemy\pool\base.py", line 678, in __init__
    self.__connect()
  File "C:\python\lib\site-packages\sqlalchemy\pool\base.py", line 902, in __connect
    with util.safe_reraise():
  File "C:\python\lib\site-packages\sqlalchemy\util\langhelpers.py", line 147, in __exit__
    raise exc_value.with_traceback(exc_tb)
  File "C:\python\lib\site-packages\sqlalchemy\pool\base.py", line 898, in __connect
    self.dbapi_connection = connection = pool._invoke_creator(self)
  File "C:\python\lib\site-packages\sqlalchemy\engine\create.py", line 637, in connect
    return dialect.connect(*cargs, **cparams)
  File "C:\python\lib\site-packages\sqlalchemy\engine\default.py", line 615, in connect
    return self.loaded_dbapi.connect(*cargs, **cparams)
  File "C:\python\lib\site-packages\psycopg2\__init__.py", line 122, in connect
    conn = _connect(dsn, connection_factory=connection_factory, **kwasync)
psycopg2.OperationalError

The above exception was the direct cause of the following exception:

Traceback (most recent call last):
  File "C:\python\lib\multiprocessing\process.py", line 314, in _bootstrap
    self.run()
  File "C:\python\lib\multiprocessing\process.py", line 108, in run
    self._target(*self._args, **self._kwargs)
  File "C:\python\lib\site-packages\uvicorn\_subprocess.py", line 76, in subprocess_started
    target(sockets=sockets)
  File "C:\python\lib\site-packages\uvicorn\server.py", line 61, in run
    return asyncio.run(self.serve(sockets=sockets))
  File "C:\python\lib\asyncio\runners.py", line 44, in run
    return loop.run_until_complete(main)
  File "C:\python\lib\asyncio\base_events.py", line 646, in run_until_complete
    return future.result()
  File "C:\python\lib\site-packages\uvicorn\server.py", line 68, in serve
    config.load()
  File "C:\python\lib\site-packages\uvicorn\config.py", line 467, in load
    self.loaded_app = import_from_string(self.app)
  File "C:\python\lib\site-packages\uvicorn\importer.py", line 21, in import_from_string
    module = importlib.import_module(module_str)
  File "C:\python\lib\importlib\__init__.py", line 126, in import_module
    return _bootstrap._gcd_import(name[level:], package, level)
  File "<frozen importlib._bootstrap>", line 1050, in _gcd_import
  File "<frozen importlib._bootstrap>", line 1027, in _find_and_load
  File "<frozen importlib._bootstrap>", line 1006, in _find_and_load_unlocked
  File "<frozen importlib._bootstrap>", line 688, in _load_unlocked
  File "<frozen importlib._bootstrap_external>", line 883, in exec_module
  File "<frozen importlib._bootstrap>", line 241, in _call_with_frames_removed
  File "D:\ttemp1\python23\fastapi-postgresql-crud\app\main.py", line 6, in <module>
    models.Base.metadata.create_all(bind=engine)
  File "C:\python\lib\site-packages\sqlalchemy\sql\schema.py", line 5792, in create_all
    bind._run_ddl_visitor(
  File "C:\python\lib\site-packages\sqlalchemy\engine\base.py", line 3238, in _run_ddl_visitor
    with self.begin() as conn:
  File "C:\python\lib\contextlib.py", line 135, in __enter__
    return next(self.gen)
  File "C:\python\lib\site-packages\sqlalchemy\engine\base.py", line 3228, in begin
    with self.connect() as conn:
  File "C:\python\lib\site-packages\sqlalchemy\engine\base.py", line 3264, in connect
    return self._connection_cls(self)
  File "C:\python\lib\site-packages\sqlalchemy\engine\base.py", line 147, in __init__
    Connection._handle_dbapi_exception_noconnection(
  File "C:\python\lib\site-packages\sqlalchemy\engine\base.py", line 2426, in _handle_dbapi_exception_noconnection
    raise sqlalchemy_exception.with_traceback(exc_info[2]) from e
  File "C:\python\lib\site-packages\sqlalchemy\engine\base.py", line 145, in __init__
    self._dbapi_connection = engine.raw_connection()
  File "C:\python\lib\site-packages\sqlalchemy\engine\base.py", line 3288, in raw_connection
    return self.pool.connect()
  File "C:\python\lib\site-packages\sqlalchemy\pool\base.py", line 452, in connect
    return _ConnectionFairy._checkout(self)
  File "C:\python\lib\site-packages\sqlalchemy\pool\base.py", line 1267, in _checkout
    fairy = _ConnectionRecord.checkout(pool)
  File "C:\python\lib\site-packages\sqlalchemy\pool\base.py", line 716, in checkout
    rec = pool._do_get()
  File "C:\python\lib\site-packages\sqlalchemy\pool\impl.py", line 169, in _do_get
    with util.safe_reraise():
  File "C:\python\lib\site-packages\sqlalchemy\util\langhelpers.py", line 147, in __exit__
    raise exc_value.with_traceback(exc_tb)
  File "C:\python\lib\site-packages\sqlalchemy\pool\impl.py", line 167, in _do_get
    return self._create_connection()
  File "C:\python\lib\site-packages\sqlalchemy\pool\base.py", line 393, in _create_connection
    return _ConnectionRecord(self)
  File "C:\python\lib\site-packages\sqlalchemy\pool\base.py", line 678, in __init__
    self.__connect()
  File "C:\python\lib\site-packages\sqlalchemy\pool\base.py", line 902, in __connect
    with util.safe_reraise():
  File "C:\python\lib\site-packages\sqlalchemy\util\langhelpers.py", line 147, in __exit__
    raise exc_value.with_traceback(exc_tb)
  File "C:\python\lib\site-packages\sqlalchemy\pool\base.py", line 898, in __connect
    self.dbapi_connection = connection = pool._invoke_creator(self)
  File "C:\python\lib\site-packages\sqlalchemy\engine\create.py", line 637, in connect
    return dialect.connect(*cargs, **cparams)
  File "C:\python\lib\site-packages\sqlalchemy\engine\default.py", line 615, in connect
    return self.loaded_dbapi.connect(*cargs, **cparams)
  File "C:\python\lib\site-packages\psycopg2\__init__.py", line 122, in connect
    conn = _connect(dsn, connection_factory=connection_factory, **kwasync)
sqlalchemy.exc.OperationalError: (psycopg2.OperationalError)
(Background on this error at: https://sqlalche.me/e/20/e3q8)
